2024-05-20 08:51:46 ERROR Traceback (most recent call last):
  File "C:\Users\Lenovo\nizaanth\Lib\site-packages\wandb\cli\cli.py", line 108, in wrapper
    return func(*args, **kwargs)
           ^^^^^^^^^^^^^^^^^^^^^
  File "C:\Users\Lenovo\nizaanth\Lib\site-packages\wandb\cli\cli.py", line 252, in login
    wandb.login(
  File "C:\Users\Lenovo\nizaanth\Lib\site-packages\wandb\sdk\wandb_login.py", line 84, in login
    configured = _login(
                 ^^^^^^^
  File "C:\Users\Lenovo\nizaanth\Lib\site-packages\wandb\sdk\wandb_login.py", line 334, in _login
    wlogin.prompt_api_key()
  File "C:\Users\Lenovo\nizaanth\Lib\site-packages\wandb\sdk\wandb_login.py", line 263, in prompt_api_key
    raise UsageError("api_key not configured (no-tty). call " + directive)
wandb.errors.UsageError: api_key not configured (no-tty). call wandb login [your_api_key]

